{
 "cells": [
  {
   "cell_type": "code",
   "execution_count": null,
   "id": "e3729594",
   "metadata": {},
   "outputs": [
    {
     "name": "stderr",
     "output_type": "stream",
     "text": [
      "ERROR:root:Internal Python error in the inspect module.\n",
      "Below is the traceback from this internal error.\n",
      "\n",
      "ERROR:root:Internal Python error in the inspect module.\n",
      "Below is the traceback from this internal error.\n",
      "\n",
      "ERROR:root:Internal Python error in the inspect module.\n",
      "Below is the traceback from this internal error.\n",
      "\n"
     ]
    },
    {
     "name": "stdout",
     "output_type": "stream",
     "text": [
      "Traceback (most recent call last):\n",
      "  File \"/home/ayushman.singh/anaconda3/envs/tflow/lib/python3.7/site-packages/IPython/core/interactiveshell.py\", line 3441, in run_code\n",
      "    exec(code_obj, self.user_global_ns, self.user_ns)\n",
      "  File \"<ipython-input-3-4ce41bd7fb0e>\", line 1, in <module>\n",
      "    from tensorflow_core import estimator\n",
      "ImportError: cannot import name 'estimator' from 'tensorflow_core' (/home/ayushman.singh/anaconda3/envs/tflow/lib/python3.7/site-packages/tensorflow_core/__init__.py)\n",
      "\n",
      "During handling of the above exception, another exception occurred:\n",
      "\n",
      "Traceback (most recent call last):\n",
      "  File \"/home/ayushman.singh/anaconda3/envs/tflow/lib/python3.7/site-packages/IPython/core/interactiveshell.py\", line 2061, in showtraceback\n",
      "    stb = value._render_traceback_()\n",
      "AttributeError: 'ImportError' object has no attribute '_render_traceback_'\n",
      "\n",
      "During handling of the above exception, another exception occurred:\n",
      "\n",
      "Traceback (most recent call last):\n",
      "  File \"/home/ayushman.singh/anaconda3/envs/tflow/lib/python3.7/site-packages/IPython/core/ultratb.py\", line 1101, in get_records\n",
      "    return _fixed_getinnerframes(etb, number_of_lines_of_context, tb_offset)\n",
      "  File \"/home/ayushman.singh/anaconda3/envs/tflow/lib/python3.7/site-packages/IPython/core/ultratb.py\", line 248, in wrapped\n",
      "    return f(*args, **kwargs)\n",
      "  File \"/home/ayushman.singh/anaconda3/envs/tflow/lib/python3.7/site-packages/IPython/core/ultratb.py\", line 281, in _fixed_getinnerframes\n",
      "    records = fix_frame_records_filenames(inspect.getinnerframes(etb, context))\n",
      "  File \"/home/ayushman.singh/anaconda3/envs/tflow/lib/python3.7/inspect.py\", line 1502, in getinnerframes\n",
      "    frameinfo = (tb.tb_frame,) + getframeinfo(tb, context)\n",
      "  File \"/home/ayushman.singh/anaconda3/envs/tflow/lib/python3.7/inspect.py\", line 1460, in getframeinfo\n",
      "    filename = getsourcefile(frame) or getfile(frame)\n",
      "  File \"/home/ayushman.singh/anaconda3/envs/tflow/lib/python3.7/inspect.py\", line 696, in getsourcefile\n",
      "    if getattr(getmodule(object, filename), '__loader__', None) is not None:\n",
      "  File \"/home/ayushman.singh/anaconda3/envs/tflow/lib/python3.7/inspect.py\", line 733, in getmodule\n",
      "    if ismodule(module) and hasattr(module, '__file__'):\n",
      "  File \"/home/ayushman.singh/anaconda3/envs/tflow/lib/python3.7/site-packages/tensorflow/__init__.py\", line 50, in __getattr__\n",
      "    module = self._load()\n",
      "  File \"/home/ayushman.singh/anaconda3/envs/tflow/lib/python3.7/site-packages/tensorflow/__init__.py\", line 44, in _load\n",
      "    module = _importlib.import_module(self.__name__)\n",
      "  File \"/home/ayushman.singh/anaconda3/envs/tflow/lib/python3.7/importlib/__init__.py\", line 127, in import_module\n",
      "    return _bootstrap._gcd_import(name[level:], package, level)\n",
      "  File \"<frozen importlib._bootstrap>\", line 1006, in _gcd_import\n",
      "  File \"<frozen importlib._bootstrap>\", line 983, in _find_and_load\n",
      "  File \"<frozen importlib._bootstrap>\", line 965, in _find_and_load_unlocked\n",
      "ModuleNotFoundError: No module named 'tensorflow_core.estimator'\n",
      "Traceback (most recent call last):\n",
      "  File \"/home/ayushman.singh/anaconda3/envs/tflow/lib/python3.7/site-packages/IPython/core/interactiveshell.py\", line 3441, in run_code\n",
      "    exec(code_obj, self.user_global_ns, self.user_ns)\n",
      "  File \"<ipython-input-3-4ce41bd7fb0e>\", line 1, in <module>\n",
      "    from tensorflow_core import estimator\n",
      "ImportError: cannot import name 'estimator' from 'tensorflow_core' (/home/ayushman.singh/anaconda3/envs/tflow/lib/python3.7/site-packages/tensorflow_core/__init__.py)\n",
      "\n",
      "During handling of the above exception, another exception occurred:\n",
      "\n",
      "Traceback (most recent call last):\n",
      "  File \"/home/ayushman.singh/anaconda3/envs/tflow/lib/python3.7/site-packages/IPython/core/interactiveshell.py\", line 2061, in showtraceback\n",
      "    stb = value._render_traceback_()\n",
      "AttributeError: 'ImportError' object has no attribute '_render_traceback_'\n",
      "\n",
      "During handling of the above exception, another exception occurred:\n",
      "\n",
      "Traceback (most recent call last):\n",
      "  File \"/home/ayushman.singh/anaconda3/envs/tflow/lib/python3.7/site-packages/IPython/core/interactiveshell.py\", line 3361, in run_ast_nodes\n",
      "    if (await self.run_code(code, result,  async_=asy)):\n",
      "  File \"/home/ayushman.singh/anaconda3/envs/tflow/lib/python3.7/site-packages/IPython/core/interactiveshell.py\", line 3458, in run_code\n",
      "    self.showtraceback(running_compiled_code=True)\n",
      "  File \"/home/ayushman.singh/anaconda3/envs/tflow/lib/python3.7/site-packages/IPython/core/interactiveshell.py\", line 2064, in showtraceback\n",
      "    value, tb, tb_offset=tb_offset)\n",
      "  File \"/home/ayushman.singh/anaconda3/envs/tflow/lib/python3.7/site-packages/IPython/core/ultratb.py\", line 1368, in structured_traceback\n",
      "    self, etype, value, tb, tb_offset, number_of_lines_of_context)\n",
      "  File \"/home/ayushman.singh/anaconda3/envs/tflow/lib/python3.7/site-packages/IPython/core/ultratb.py\", line 1268, in structured_traceback\n",
      "    self, etype, value, tb, tb_offset, number_of_lines_of_context\n",
      "  File \"/home/ayushman.singh/anaconda3/envs/tflow/lib/python3.7/site-packages/IPython/core/ultratb.py\", line 1125, in structured_traceback\n",
      "    tb_offset)\n",
      "  File \"/home/ayushman.singh/anaconda3/envs/tflow/lib/python3.7/site-packages/IPython/core/ultratb.py\", line 1082, in format_exception_as_a_whole\n",
      "    last_unique, recursion_repeat = find_recursion(orig_etype, evalue, records)\n",
      "  File \"/home/ayushman.singh/anaconda3/envs/tflow/lib/python3.7/site-packages/IPython/core/ultratb.py\", line 382, in find_recursion\n",
      "    return len(records), 0\n",
      "TypeError: object of type 'NoneType' has no len()\n",
      "\n",
      "During handling of the above exception, another exception occurred:\n",
      "\n",
      "Traceback (most recent call last):\n",
      "  File \"/home/ayushman.singh/anaconda3/envs/tflow/lib/python3.7/site-packages/IPython/core/interactiveshell.py\", line 2061, in showtraceback\n",
      "    stb = value._render_traceback_()\n",
      "AttributeError: 'TypeError' object has no attribute '_render_traceback_'\n",
      "\n",
      "During handling of the above exception, another exception occurred:\n",
      "\n",
      "Traceback (most recent call last):\n",
      "  File \"/home/ayushman.singh/anaconda3/envs/tflow/lib/python3.7/site-packages/IPython/core/ultratb.py\", line 1101, in get_records\n",
      "    return _fixed_getinnerframes(etb, number_of_lines_of_context, tb_offset)\n",
      "  File \"/home/ayushman.singh/anaconda3/envs/tflow/lib/python3.7/site-packages/IPython/core/ultratb.py\", line 248, in wrapped\n",
      "    return f(*args, **kwargs)\n",
      "  File \"/home/ayushman.singh/anaconda3/envs/tflow/lib/python3.7/site-packages/IPython/core/ultratb.py\", line 281, in _fixed_getinnerframes\n",
      "    records = fix_frame_records_filenames(inspect.getinnerframes(etb, context))\n",
      "  File \"/home/ayushman.singh/anaconda3/envs/tflow/lib/python3.7/inspect.py\", line 1502, in getinnerframes\n",
      "    frameinfo = (tb.tb_frame,) + getframeinfo(tb, context)\n",
      "  File \"/home/ayushman.singh/anaconda3/envs/tflow/lib/python3.7/inspect.py\", line 1460, in getframeinfo\n",
      "    filename = getsourcefile(frame) or getfile(frame)\n",
      "  File \"/home/ayushman.singh/anaconda3/envs/tflow/lib/python3.7/inspect.py\", line 696, in getsourcefile\n",
      "    if getattr(getmodule(object, filename), '__loader__', None) is not None:\n",
      "  File \"/home/ayushman.singh/anaconda3/envs/tflow/lib/python3.7/inspect.py\", line 733, in getmodule\n",
      "    if ismodule(module) and hasattr(module, '__file__'):\n",
      "  File \"/home/ayushman.singh/anaconda3/envs/tflow/lib/python3.7/site-packages/tensorflow/__init__.py\", line 50, in __getattr__\n",
      "    module = self._load()\n",
      "  File \"/home/ayushman.singh/anaconda3/envs/tflow/lib/python3.7/site-packages/tensorflow/__init__.py\", line 44, in _load\n",
      "    module = _importlib.import_module(self.__name__)\n",
      "  File \"/home/ayushman.singh/anaconda3/envs/tflow/lib/python3.7/importlib/__init__.py\", line 127, in import_module\n",
      "    return _bootstrap._gcd_import(name[level:], package, level)\n",
      "  File \"<frozen importlib._bootstrap>\", line 1006, in _gcd_import\n",
      "  File \"<frozen importlib._bootstrap>\", line 983, in _find_and_load\n",
      "  File \"<frozen importlib._bootstrap>\", line 965, in _find_and_load_unlocked\n",
      "ModuleNotFoundError: No module named 'tensorflow_core.estimator'\n",
      "Traceback (most recent call last):\n",
      "  File \"/home/ayushman.singh/anaconda3/envs/tflow/lib/python3.7/site-packages/IPython/core/interactiveshell.py\", line 3441, in run_code\n",
      "    exec(code_obj, self.user_global_ns, self.user_ns)\n",
      "  File \"<ipython-input-3-4ce41bd7fb0e>\", line 1, in <module>\n",
      "    from tensorflow_core import estimator\n",
      "ImportError: cannot import name 'estimator' from 'tensorflow_core' (/home/ayushman.singh/anaconda3/envs/tflow/lib/python3.7/site-packages/tensorflow_core/__init__.py)\n",
      "\n",
      "During handling of the above exception, another exception occurred:\n",
      "\n",
      "Traceback (most recent call last):\n",
      "  File \"/home/ayushman.singh/anaconda3/envs/tflow/lib/python3.7/site-packages/IPython/core/interactiveshell.py\", line 2061, in showtraceback\n",
      "    stb = value._render_traceback_()\n",
      "AttributeError: 'ImportError' object has no attribute '_render_traceback_'\n",
      "\n",
      "During handling of the above exception, another exception occurred:\n",
      "\n",
      "Traceback (most recent call last):\n",
      "  File \"/home/ayushman.singh/anaconda3/envs/tflow/lib/python3.7/site-packages/IPython/core/interactiveshell.py\", line 3361, in run_ast_nodes\n",
      "    if (await self.run_code(code, result,  async_=asy)):\n",
      "  File \"/home/ayushman.singh/anaconda3/envs/tflow/lib/python3.7/site-packages/IPython/core/interactiveshell.py\", line 3458, in run_code\n",
      "    self.showtraceback(running_compiled_code=True)\n",
      "  File \"/home/ayushman.singh/anaconda3/envs/tflow/lib/python3.7/site-packages/IPython/core/interactiveshell.py\", line 2064, in showtraceback\n",
      "    value, tb, tb_offset=tb_offset)\n",
      "  File \"/home/ayushman.singh/anaconda3/envs/tflow/lib/python3.7/site-packages/IPython/core/ultratb.py\", line 1368, in structured_traceback\n",
      "    self, etype, value, tb, tb_offset, number_of_lines_of_context)\n",
      "  File \"/home/ayushman.singh/anaconda3/envs/tflow/lib/python3.7/site-packages/IPython/core/ultratb.py\", line 1268, in structured_traceback\n",
      "    self, etype, value, tb, tb_offset, number_of_lines_of_context\n",
      "  File \"/home/ayushman.singh/anaconda3/envs/tflow/lib/python3.7/site-packages/IPython/core/ultratb.py\", line 1125, in structured_traceback\n",
      "    tb_offset)\n",
      "  File \"/home/ayushman.singh/anaconda3/envs/tflow/lib/python3.7/site-packages/IPython/core/ultratb.py\", line 1082, in format_exception_as_a_whole\n",
      "    last_unique, recursion_repeat = find_recursion(orig_etype, evalue, records)\n",
      "  File \"/home/ayushman.singh/anaconda3/envs/tflow/lib/python3.7/site-packages/IPython/core/ultratb.py\", line 382, in find_recursion\n",
      "    return len(records), 0\n",
      "TypeError: object of type 'NoneType' has no len()\n",
      "\n",
      "During handling of the above exception, another exception occurred:\n",
      "\n",
      "Traceback (most recent call last):\n",
      "  File \"/home/ayushman.singh/anaconda3/envs/tflow/lib/python3.7/site-packages/IPython/core/interactiveshell.py\", line 2061, in showtraceback\n",
      "    stb = value._render_traceback_()\n",
      "AttributeError: 'TypeError' object has no attribute '_render_traceback_'\n",
      "\n",
      "During handling of the above exception, another exception occurred:\n",
      "\n",
      "Traceback (most recent call last):\n",
      "  File \"/home/ayushman.singh/anaconda3/envs/tflow/lib/python3.7/site-packages/IPython/core/interactiveshell.py\", line 2944, in _run_cell\n",
      "    return runner(coro)\n",
      "  File \"/home/ayushman.singh/anaconda3/envs/tflow/lib/python3.7/site-packages/IPython/core/async_helpers.py\", line 68, in _pseudo_sync_runner\n",
      "    coro.send(None)\n",
      "  File \"/home/ayushman.singh/anaconda3/envs/tflow/lib/python3.7/site-packages/IPython/core/interactiveshell.py\", line 3170, in run_cell_async\n",
      "    interactivity=interactivity, compiler=compiler, result=result)\n",
      "  File \"/home/ayushman.singh/anaconda3/envs/tflow/lib/python3.7/site-packages/IPython/core/interactiveshell.py\", line 3380, in run_ast_nodes\n",
      "    self.showtraceback()\n",
      "  File \"/home/ayushman.singh/anaconda3/envs/tflow/lib/python3.7/site-packages/IPython/core/interactiveshell.py\", line 2064, in showtraceback\n",
      "    value, tb, tb_offset=tb_offset)\n",
      "  File \"/home/ayushman.singh/anaconda3/envs/tflow/lib/python3.7/site-packages/IPython/core/ultratb.py\", line 1368, in structured_traceback\n",
      "    self, etype, value, tb, tb_offset, number_of_lines_of_context)\n",
      "  File \"/home/ayushman.singh/anaconda3/envs/tflow/lib/python3.7/site-packages/IPython/core/ultratb.py\", line 1268, in structured_traceback\n",
      "    self, etype, value, tb, tb_offset, number_of_lines_of_context\n",
      "  File \"/home/ayushman.singh/anaconda3/envs/tflow/lib/python3.7/site-packages/IPython/core/ultratb.py\", line 1143, in structured_traceback\n",
      "    chained_exceptions_tb_offset)\n",
      "  File \"/home/ayushman.singh/anaconda3/envs/tflow/lib/python3.7/site-packages/IPython/core/ultratb.py\", line 1082, in format_exception_as_a_whole\n",
      "    last_unique, recursion_repeat = find_recursion(orig_etype, evalue, records)\n",
      "  File \"/home/ayushman.singh/anaconda3/envs/tflow/lib/python3.7/site-packages/IPython/core/ultratb.py\", line 382, in find_recursion\n",
      "    return len(records), 0\n",
      "TypeError: object of type 'NoneType' has no len()\n",
      "\n",
      "During handling of the above exception, another exception occurred:\n",
      "\n",
      "Traceback (most recent call last):\n",
      "  File \"/home/ayushman.singh/anaconda3/envs/tflow/lib/python3.7/site-packages/IPython/core/interactiveshell.py\", line 2061, in showtraceback\n",
      "    stb = value._render_traceback_()\n",
      "AttributeError: 'TypeError' object has no attribute '_render_traceback_'\n",
      "\n",
      "During handling of the above exception, another exception occurred:\n",
      "\n",
      "Traceback (most recent call last):\n",
      "  File \"/home/ayushman.singh/anaconda3/envs/tflow/lib/python3.7/site-packages/IPython/core/ultratb.py\", line 1101, in get_records\n",
      "    return _fixed_getinnerframes(etb, number_of_lines_of_context, tb_offset)\n",
      "  File \"/home/ayushman.singh/anaconda3/envs/tflow/lib/python3.7/site-packages/IPython/core/ultratb.py\", line 248, in wrapped\n",
      "    return f(*args, **kwargs)\n",
      "  File \"/home/ayushman.singh/anaconda3/envs/tflow/lib/python3.7/site-packages/IPython/core/ultratb.py\", line 281, in _fixed_getinnerframes\n",
      "    records = fix_frame_records_filenames(inspect.getinnerframes(etb, context))\n",
      "  File \"/home/ayushman.singh/anaconda3/envs/tflow/lib/python3.7/inspect.py\", line 1502, in getinnerframes\n",
      "    frameinfo = (tb.tb_frame,) + getframeinfo(tb, context)\n",
      "  File \"/home/ayushman.singh/anaconda3/envs/tflow/lib/python3.7/inspect.py\", line 1460, in getframeinfo\n",
      "    filename = getsourcefile(frame) or getfile(frame)\n",
      "  File \"/home/ayushman.singh/anaconda3/envs/tflow/lib/python3.7/inspect.py\", line 696, in getsourcefile\n",
      "    if getattr(getmodule(object, filename), '__loader__', None) is not None:\n",
      "  File \"/home/ayushman.singh/anaconda3/envs/tflow/lib/python3.7/inspect.py\", line 733, in getmodule\n",
      "    if ismodule(module) and hasattr(module, '__file__'):\n",
      "  File \"/home/ayushman.singh/anaconda3/envs/tflow/lib/python3.7/site-packages/tensorflow/__init__.py\", line 50, in __getattr__\n",
      "    module = self._load()\n",
      "  File \"/home/ayushman.singh/anaconda3/envs/tflow/lib/python3.7/site-packages/tensorflow/__init__.py\", line 44, in _load\n",
      "    module = _importlib.import_module(self.__name__)\n",
      "  File \"/home/ayushman.singh/anaconda3/envs/tflow/lib/python3.7/importlib/__init__.py\", line 127, in import_module\n",
      "    return _bootstrap._gcd_import(name[level:], package, level)\n",
      "  File \"<frozen importlib._bootstrap>\", line 1006, in _gcd_import\n",
      "  File \"<frozen importlib._bootstrap>\", line 983, in _find_and_load\n",
      "  File \"<frozen importlib._bootstrap>\", line 965, in _find_and_load_unlocked\n",
      "ModuleNotFoundError: No module named 'tensorflow_core.estimator'\n"
     ]
    }
   ],
   "source": [
    "from tensorflow_core import estimator"
   ]
  },
  {
   "cell_type": "code",
   "execution_count": null,
   "id": "4d724214",
   "metadata": {},
   "outputs": [],
   "source": []
  },
  {
   "cell_type": "code",
   "execution_count": 2,
   "id": "b3d0ac16",
   "metadata": {},
   "outputs": [],
   "source": [
    "import tensorflow as tf"
   ]
  },
  {
   "cell_type": "code",
   "execution_count": null,
   "id": "c8aee54c",
   "metadata": {},
   "outputs": [],
   "source": []
  }
 ],
 "metadata": {
  "kernelspec": {
   "display_name": "Python 3",
   "language": "python",
   "name": "python3"
  },
  "language_info": {
   "codemirror_mode": {
    "name": "ipython",
    "version": 3
   },
   "file_extension": ".py",
   "mimetype": "text/x-python",
   "name": "python",
   "nbconvert_exporter": "python",
   "pygments_lexer": "ipython3",
   "version": "3.7.10"
  }
 },
 "nbformat": 4,
 "nbformat_minor": 5
}
